Workbook

Sheet Janeiro 2024 - Escrita
A1: LEVANTAMENTO DE NEs COM DEFINIÇÃO DO MÓDULO ESCRITA FISCAL - VERSÃO DE JANEIRO/2024 (10.4A-01)
A3: NE | B3: SAI Origem | C3: Ano SAI Origem | D3: Tipo SAI Origem | E3: Responsável PSAI | F3: Responsável SAI | G3: Análise dos Erros
A4: 82013 | B4: 78709 | C4: 2023 | D4: SAL | E4: Felipi Ferreira | F4: Bruna | G4: Falha na análise da legislação - Alteração apenas para determinados CNAEs.
A5: 82300 | B5: 27258 | C5: 2013 | D5: SAIL | E5: - | F5: - | G5: -
A6: 82296 | B6: 77860 | C6: 2023 | D6: SAL | E6: Bárbara Mello | F6: Marielli | G6: Cálculo Fomentar/Produzir alterado o relatório e não avaliado todos os reflexos (Pagamento de Impostos) que montam considerando os valores do relatório.
A7: 82407 | B7: 54496 | C7: 2018 | D7: SAL | E7: - | F7: - | G7: -
A8: 83463 | B8: não possui
A9: 83882 | B9: 82422 | C9: 2023 | D9: SAL | E9: Filipe Santos | F9: Giovani | G9: Alteração na escrituração das notas e não foi tratado o registro C170 do SPED Fiscal.
A17: Total de NEs liberadas | C17: 26
A18: NE's com definição | C18: 6 | D18: =C18/C17 -> 0.23076923
A19: NeE's com definição recentes | C19: 3 | D19: =C19/C17 -> 0.11538462

Sheet Janeiro 2024 - Importação
A1: LEVANTAMENTO DE NEs COM DEFINIÇÃO DO MÓDULO IMPORTAÇÃO PADRÃO - VERSÃO DE JANEIRO/2024 (10.4A-01)
A3: NE | B3: SAI Origem | C3: Ano SAI Origem | D3: Tipo SAI Origem | E3: Responsável PSAI | F3: Responsável SAI | G3: Analise dos Erros
A4: 82915 | B4: não possui
A5: 83484 | B5: 82808 | C5: 2023 | D5: SAM | E5: Sabrine | F5: Victor
D8: NÃO TIVEMOS NE COM DEFINIÇÃO NESSA VERSÃO
A16: Total de NEs liberadas | C16: 11
A17: NE's com definição | C17: 2 | D17: =C17/C16 -> 0.18181818
A18: NE's com definição recentes | C18: 0 | D18: =C18/C16 -> 0

Sheet Fevereiro 2024 - Escrita
A1: LEVANTAMENTO DE NEs COM DEFINIÇÃO DO MÓDULO ESCRITA FISCAL - VERSÃO DE FAVEREIRO/2024 (10.4A-02)
A3: NE | B3: SAI Origem | C3: Ano SAI Origem | D3: Tipo SAI Origem | E3: Responsável PSAI | F3: Responsável SAI | G3: Análise dos Erros
A4: 82704 | B4: 22469 | C4: 2012 | D4: - | E4: - | F4: -
A5: 82702 | B5: 64148 | C5: 2020 | D5: SAL
A6: 82948 | B6: 56166 | C6: 2019
A7: 83135 | B7: 33162 | C7: 2014
A8: 83807 | B8: 73959 | C8: 2022 | D8: SAIL | E8: Daniela | F8: Patrícia
A9: 84195 | B9: não possui
A10: 84467 | B10: 83433 | C10: 2023 | D10: SAL | E10: Renan | F10: Lais | G10: Não foi pensado no comportamento do botão "Outros dados" para Matriz e Filial.
A17: Total de NEs liberadas | C17: 34
A18: NE's com definição | C18: 7 | D18: =C18/C17 -> 0.20588235
A19: NE's com definição recentes | C19: 1 | D19: =C19/C17 -> 0.029411765

Sheet Fevereiro 2024 - Importação
A1: LEVANTAMENTO DE NEs COM DEFINIÇÃO DO MÓDULO IMPORTAÇÃO PADRÃO - VERSÃO DE FAVEREIRO/2024 (10.4A-02)
A3: NE | B3: SAI Origem | C3: Ano SAI Origem | D3: Tipo SAI Origem | E3: Responsável PSAI | F3: Responsável SAI | G3: Analise dos Erros
A4: 82057 | B4: não possui
D8: NÃO TIVEMOS NE COM DEFINIÇÃO NESSA VERSÃO
A16: Total de NEs liberadas | C16: 3
A17: NE's com definição | C17: 1 | D17: =C17/C16 -> 0.33333333
A18: NE's com definição recentes | C18: 0 | D18: =C18/C16 -> 0

Sheet Março 2024 - Escrita
A1: LEVANTAMENTO DE NEs COM DEFINIÇÃO DO MÓDULO ESCRITA FISCAL - VERSÃO DE MARÇO/2024 (10.4A-03)
A3: NE | B3: SAI Origem | C3: Ano SAI Origem | D3: Tipo SAI Origem | E3: Responsável PSAI | F3: Responsável SAI | G3: Análise dos Erros
A4: 84717 | B4: 79629 | C4: 2023 | D4: SAL | E4: Felipi Ferreira | F4: Giovani | G4: A dedução do imposto 63 não considera o período do pagamento.
A5: 85180 | B5: 84395 | C5: 2024 | D5: SAIL | E5: Bárbara Mello | F5: Lais | G5: Definição incompleta referente ao código do item.
A16: Total de NEs liberadas | C16: 31
A17: NE's com definição | C17: 2 | D17: =C17/C16 -> 0.064516129
A18: NE's com definição recentes | C18: 2 | D18: =C18/C16 -> 0.064516129

Sheet Março 2024 - Importação
A1: LEVANTAMENTO DE NEs COM DEFINIÇÃO DO MÓDULO IMPORTAÇÃO PADRÃO - VERSÃO DE MARÇO/2024 (10.4A-03)
A3: NE | B3: SAI Origem | C3: Ano SAI Origem | D3: Tipo SAI Origem | E3: Responsável PSAI | F3: Responsável SAI | G3: Analise dos Erros
A4: 83692 | B4: 67081 | C4: 2020 | D4: NE | E4: Victor | F4: Richardson
A5: 84808 | B5: 83916 | C5: 2024 | D5: SAM | E5: Victor | F5: Victor | G5: Erro de threads.
A16: Total de NEs liberadas | C16: 11
A17: NE's com definição | C17: 2 | D17: =C17/C16 -> 0.18181818
A18: NE's com definição recentes | C18: 1 | D18: =C18/C16 -> 0.090909091

Sheet Abril 2024 - Escrita
A1: LEVANTAMENTO DE NEs COM DEFINIÇÃO DO MÓDULO ESCRITA FISCAL - VERSÃO DE Abril/2024 (10.4A-04)
A3: NE | B3: SAI Origem | C3: Ano SAI Origem | D3: Tipo SAI Origem | E3: Responsável PSAI | F3: Responsável SAI | G3: Análise dos Erros
A4: 83603 | B4: não possui | C4: - | D4: - | E4: - | F4: -
A5: 83775 | B5: 68604 | C5: 2020 | D5: SAM | E5: Patrícia Machado | F5: Mariana S.
A6: 83856 | B6: 84508 | C6: 2024 | D6: SAL | E6: Bárbara Melo | F6: Lais | G6: Prever o mesmo produto mais de uma vez na nota. Tratar as mesmas validações na Escrita e Importação.
A7: 85265 | B7: 78693 | C7: 2023 | D7: SAM | E7: Felipi Ferreira | F7: Bruna | G7: Tributos federais - Sempre avaliar os reflexos na Folha.
A8: 85351 | B8: 78961 | C8: 2023 | D8: SAIL | E8: Juliana | F8: Giovani | G8: NE Interna.
A9: 85349 | B9: 78961 | C9: 2023 | D9: SAIL | E9: Juliana | F9: Giovani | G9: NE Interna.
A10: 85687 | B10: 78961 | C10: 2023 | D10: SAIL | E10: Juliana | F10: Giovani | G10: Campos novos - Analisar se o campo terá que sempre ser gerado, ou vai existir possibilidade de gerar ou não.
A11: 85713 | B11: 43896 | C11: 2016 | D11: SAIL | E11: Patrícia C. | F11: Edgar
A16: Total de NEs liberadas | C16: 33
A17: NE's com definição | C17: 8 | D17: =C17/C16 -> 0.24242424
A18: NE's com definição recentes | C18: 3 | D18: =C18/C16 -> 0.090909091

Sheet Abril 2024 - Importação
A1: LEVANTAMENTO DE NEs COM DEFINIÇÃO DO MÓDULO IMPORTAÇÃO PADRÃO - VERSÃO DE Abril/2024 (10.4A-04)
A3: NE | B3: SAI Origem | C3: Ano SAI Origem | D3: Tipo SAI Origem | E3: Responsável PSAI | F3: Responsável SAI | G3: Analise dos Erros
A4: 85420 | B4: 84509 | C4: 2024 | D4: SAM | E4: Bárbara Melo | F4: Lais | G4: NE interna.
A5: 85498 | B5: 82171 | C5: 2023 | D5: SAM | E5: Sabrine | F5: Victor
A6: 85512 | B6: 83869 | C6: 2024 | D6: SAM | E6: Carolina | F6: Victor
A18: Total de NEs liberadas | C18: 6
A19: NE's com definição | C19: 3 | D19: =C19/C18 -> 0.5
A20: NE's com definição recentes | C20: 2 | D20: =C20/C18 -> 0.33333333

Sheet Maio 2024 - Escrita
A1: LEVANTAMENTO DE NEs COM DEFINIÇÃO DO MÓDULO ESCRITA FISCAL - VERSÃO DE Maio/2024 (10.4A-05)
A3: NE | B3: SAI Origem | C3: Ano SAI Origem | D3: Tipo SAI Origem | E3: Responsável PSAI | F3: Responsável SAI | G3: Análise dos Erros
A4: 84083 | B4: 28978 | C4: 2014 | D4: SAIL | E4: - | F4: -
A5: 84080 | B5: 51010 | C5: 2018 | D5: NE | E5: - | F5: -
A6: 84252 | B6: 75155 | C6: 2022 | D6: SAL | E6: Cibele | F6: Marielli | G6: Definições para alterar a escrituração sem detalhar os registros que não devem gerar mais.
A7: 84590 | B7: 29609 | C7: 2014 | D7: - | E7: - | F7: -
A8: 85374 | B8: 62564 | C8: 2019 | D8: - | E8: - | F8: -
A9: 85760 | B9: 14863 | C9: 2011 | D9: - | E9: - | F9: -
A10: 85835 | B10: 78961 | C10: 2023 | D10: SAIL | E10: Juliana | F10: Giovani | G10: NE Interna.
A11: 85920 | B11: 84450 | C11: 2024 | D11: SAIL | E11: Juliana | F11: Lais | G11: NE Interna.
A12: 85978 | B12: 85276 | C12: 2024 | D12: SAIL | E12: Juliana | F12: Giovani | G12: Faltou detalhar nas rotinas a consideração de Retificadora ou Original do DAS API.
A13: 86078 | B13: 78961 | C13: 2023 | D13: SAIL | E13: Juliana | F13: Giovani | G13: Gestta Processos, não foi definido que a conclusão de relatórios deve ser no próprio relatório conforme padrão. Falta de conhecimento.
A14: 86137 | B14: 84250 | C14: 2024 | D14: SAM | E14: Rafaela | F14: Giovani | G14: Definido a consideração dos sócios de forma anual não considerando o período do informativo.
A15: 86302 | B15: 78961 | C15: 2023 | D15: SAIL | E15: Juliana | F15: Giovani | G15: Foi definido de forma incorreta quando o valor da Folha de Salários for zerado em algum período.
A16: 86474 | B16: 78961 | C16: 2023 | D16: SAIL | E16: Juliana | F16: Giovani | G16: Não foi definido o comportamento quando a empresa Filial é inativa. Não tinha a condição para teste.
A21: Total de NEs liberadas | C21: 48
A22: NE's com definição | C22: 13 | D22: =C22/C21 -> 0.27083333
A23: NE's com definição recentes | C23: 6 | D23: =C23/C21 -> 0.125

Sheet Maio 2024 - Importação
A1: LEVANTAMENTO DE NEs COM DEFINIÇÃO DO MÓDULO IMPORTAÇÃO PADRÃO - VERSÃO DE Maio/2024 (10.4A-05)
A3: NE | B3: SAI Origem | C3: Ano SAI Origem | D3: Tipo SAI Origem | E3: Responsável PSAI | F3: Responsável SAI | G3: Analise dos Erros
A4: 84562 | B4: 46656 | C4: 2017 | D4: - | E4: - | F4: -
A5: 84809 | B5: não possui | C5: - | D5: - | E5: - | F5: -
A18: Total de NEs liberadas | C18: 11
A19: NE's com definição | C19: 2 | D19: =C19/C18 -> 0.18181818
A20: NE's com definição recentes | C20: 0 | D20: =C20/C18 -> 0

Sheet Junho 2024 - Escrita
A1: LEVANTAMENTO DE NEs COM DEFINIÇÃO DO MÓDULO ESCRITA FISCAL - VERSÃO DE Junho/2024 (10.4A-06)
A3: NE | B3: SAI Origem | C3: Ano SAI Origem | D3: Tipo SAI Origem | E3: Responsável PSAI | F3: Responsável SAI | G3: Análise dos Erros
A4: 85390 | B4: 67944 | C4: 2020 | D4: SAM
A5: 86310 | B5: não possui | G5: NE interna.
A6: 86529 | B6: 73246 | C6: 2021 | D6: SAL | E6: - | F6: -
A7: 86557 | B7: não possui | G7: NE interna.
A8: 86997 | B8: não possui | G8: NE interna.
A19: Total de NEs liberadas | C19: 24
A20: NE's com definição | C20: 5 | D20: =C20/C19 -> 0.20833333
A21: NE's com definição recentes | C21: 0 | D21: =C21/C19 -> 0

Sheet Junho 2024 - Importação
A1: LEVANTAMENTO DE NEs COM DEFINIÇÃO DO MÓDULO IMPORTAÇÃO PADRÃO - VERSÃO DE JUNHO/2024 (10.4A-06)
A3: NE | B3: SAI Origem | C3: Ano SAI Origem | D3: Tipo SAI Origem | E3: Responsável PSAI | F3: Responsável SAI | G3: Analise dos Erros
A4: 84634 | B4: não possui
A15: Total de NEs liberadas | C15: 13
A16: NE's com definição | C16: 1 | D16: =C16/C15 -> 0.076923077
A17: NE's com definição recentes | C17: 0 | D17: =C17/C15 -> 0

Sheet Julho 2024 - Escrita
A1: LEVANTAMENTO DE NEs COM DEFINIÇÃO DO MÓDULO ESCRITA FISCAL - VERSÃO DE JULHO/2024 (10.4A-07)
A3: NE | B3: SAI Origem | C3: Ano SAI Origem | D3: Tipo SAI Origem | E3: Responsável PSAI | F3: Responsável SAI | G3: Análise dos Erros
A4: 87481 | B4: 83055 | C4: 2023 | D4: SAIL | E4: Juliana | F4: Lais | G4: Copiando comportamentos de outras definições, sem confirmar se está correto.
A5: 87463 | B5: 85647 | C5: 2024 | D5: SAL | E5: Filipe Santos | F5: Bruna | G5: Não detalhou a consideração dos novos CFOPs junto com as espécies das notas.
A6: 87174 | B6: 7898 | C6: 2008 | D6: SAL
A7: 87148 | B7: 80366 | C7: 2023 | D7: SAL | E7: Felipi Ferreira | F7: Bruna | G7: Detalhado os registros do SPED referente ao cadastro do produto e esquecido o registro 0220.
A8: 86556 | B8: não possui
A9: 85785 | B9: 76192 | C9: 2022 | D9: SAIL | E9: Mariana F. | F9: Giovani | G9: Detalhar o demonstrativo/relatórios considerando todas as regras definidas na apuração.
A19: Total de NEs liberadas | C19: 30
A20: NE's com definição | C20: 6 | D20: =C20/C19 -> 0.2
A21: NE's com definição recentes | C21: 4 | D21: =C21/C19 -> 0.13333333

Sheet Julho 2024 - Importação
A1: LEVANTAMENTO DE NEs COM DEFINIÇÃO DO MÓDULO IMPORTAÇÃO PADRÃO - VERSÃO DE JULHO/2024 (10.4A-07)
A3: NE | B3: SAI Origem | C3: Ano SAI Origem | D3: Tipo SAI Origem | E3: Responsável PSAI | F3: Responsável SAI | G3: Analise dos Erros
A15: Total de NEs liberadas | C15: 8
A16: NE's com definição | C16: 0 | D16: =C16/C15 -> 0
A17: NE's com definição recentes | C17: 0 | D17: =C17/C15 -> 0

Sheet Agosto 2024 - Escrita
A1: LEVANTAMENTO DE NEs COM DEFINIÇÃO DO MÓDULO ESCRITA FISCAL - VERSÃO DE AGOSTO/2024 (10.4A-08)
A3: NE | B3: SAI Origem | C3: Ano SAI Origem | D3: Tipo SAI Origem | E3: Responsável PSAI | F3: Responsável SAI | G3: Análise dos Erros
A4: 86273 | B4: 80230 | C4: 2023 | D4: SAIL | E4: Juliana | F4: Lais | G4: Não tratado o regerar lançamentos contábeis para o novo valor da nota.
A5: 87966 | B5: 87350 | C5: 2024 | D5: SAIL | E5: Lais | F5: Marielli | G5: Interna
A14: Total de NEs liberadas | C14: 28
A15: NE's com definição | C15: 2 | D15: =C15/C14 -> 0.071428571
A16: NE's com definição recentes | C16: 1 | D16: =C16/C14 -> 0.035714286

Sheet Agosto 2024 - Importação
A1: LEVANTAMENTO DE NEs COM DEFINIÇÃO DO MÓDULO IMPORTAÇÃO PADRÃO - VERSÃO DE AGOSTO/2024 (10.4A-08)
A3: NE | B3: SAI Origem | C3: Ano SAI Origem | D3: Tipo SAI Origem | E3: Responsável PSAI | F3: Responsável SAI | G3: Analise dos Erros
A4: 87992 | B4: não possui
A5: 86444 | B5: não possui
A6: 86061 | B6: 85420 | C6: 2024 | D6: NE | E6: Carolina | F6: Carolina
A15: Total de NEs liberadas | C15: 9
A16: NE's com definição | C16: 3 | D16: =C16/C15 -> 0.33333333
A17: NE's com definição recentes | C17: 1 | D17: =C17/C15 -> 0.11111111

Sheet Setembro 2024 - Escrita
A1: LEVANTAMENTO DE NEs COM DEFINIÇÃO DO MÓDULO ESCRITA FISCAL - VERSÃO DE SETEMBRO/2024 (10.4A-09)
A3: NE | B3: SAI Origem | C3: Ano SAI Origem | D3: Tipo SAI Origem | E3: Responsável PSAI | F3: Responsável SAI | G3: Análise dos Erros
A4: 87646 | B4: 35685 | C4: 2015 | D4: SAIL
A5: 88512 | B5: 73747 | C5: 2024 | D5: SAIL | E5: Lais | F5: Marielli | G5: Definição para atualização de banco, quando o campo é uma combo deve ser avaliado se vai existir a possibilidade do campo estar desabilitado e como tem que tratar na atualização.
A14: Total de NEs liberadas | C14: 21
A15: NE's com definição | C15: 2 | D15: =C15/C14 -> 0.095238095
A16: NE's com definição recentes | C16: 1 | D16: =C16/C14 -> 0.047619048

Sheet Setembro 2024 - Importação
A1: LEVANTAMENTO DE NEs COM DEFINIÇÃO DO MÓDULO IMPORTAÇÃO PADRÃO - VERSÃO DE SETEMBRO/2024 (10.4A-09)
A3: NE | B3: SAI Origem | C3: Ano SAI Origem | D3: Tipo SAI Origem | E3: Responsável PSAI | F3: Responsável SAI | G3: Analise dos Erros
A4: 86240 | B4: não possui
A5: 88483 | B5: não possui
A15: Total de NEs liberadas | C15: 9
A16: NE's com definição | C16: 2 | D16: =C16/C15 -> 0.22222222
A17: NE's com definição recentes | C17: 0 | D17: =C17/C15 -> 0

Sheet Outubro 2024 - Escrita
A1: LEVANTAMENTO DE NEs COM DEFINIÇÃO DO MÓDULO ESCRITA FISCAL - VERSÃO DE OUTUBRO/2024 (10.4A-10)
A3: NE | B3: SAI Origem | C3: Ano SAI Origem | D3: Tipo SAI Origem | E3: Responsável PSAI | F3: Responsável SAI | G3: Análise dos Erros
A4: 87382 | B4: não possui
A5: 88237 | B5: 86273 | C5: 2024 | D5: NE | E5: Juliana/Luciana | F5: Lais | G5: Não foi definido todas as formas de contabilização. Por nota e na Integração não considerando a opção "Gera lançamentos contábeis por nota.
A6: 89145 | B6: 85209 | C6: 2024 | D6: SAIL | E6: Juliana | F6: Lais | G6: Não foi observado que alguns campos definidos não eram campos obrigatórios, e não definiu quando não tiver informação.
A7: 89257 | B7: 76208 | C7: 2024 | D7: SAM | E7: Renan | F7: Giovani | G7: Utilitários. | H7: Crítico
A8: 89278 | B8: 83219 | C8: 2023 | D8: SAL | E8: Cibele | F8: Lais | G8: Não foi definido corretamente o registro da DCIP conforme o subtipo da operação. Subtipo estono de débito / registro outros créditos.
A9: 89395 | B9: 33209 | C9: 2014 | D9: SAIL
A10: 89381 | B10: 85105 | C10: 2024 | D10: SAL | E10: Bárbara L | F10: Giovani | G10: Não foi definido as mesmas regras no SPED que foram definidas para o cálculo. Marcação do parâmetros detalhado na apuração e não no SPED.
A11: 89524 | B11: 88173 | C11: 2024 | D11: SAIL | E11: Bárbara Melo | F11: Lais | G11: Não foi entendido que o comportamento da versão de mercado não se encaixava para a nova situação.
A17: Total de NEs liberadas | C17: 22
A18: NE's com definição | C18: 8 | D18: =C18/C17 -> 0.36363636
A19: NE's com definição recentes | C19: 6 | D19: =C19/C17 -> 0.27272727

Sheet Outubro 2024 - Importação
A1: LEVANTAMENTO DE NEs COM DEFINIÇÃO DO MÓDULO IMPORTAÇÃO PADRÃO - VERSÃO DE SETEMBRO/2024 (10.4A-09)
A3: NE | B3: SAI Origem | C3: Ano SAI Origem | D3: Tipo SAI Origem | E3: Responsável PSAI | F3: Responsável SAI | G3: Analise dos Erros
A4: 87915 | B4: 36739 | C4: 2015
A5: 87575 | B5: não possui
A15: Total de NEs liberadas | C15: 12
A16: NE's com definição | C16: 2 | D16: =C16/C15 -> 0.16666667
A17: NE's com definição recentes | C17: 0 | D17: =C17/C15 -> 0

Sheet Novembro 2024 - Escrita
A1: LEVANTAMENTO DE NEs COM DEFINIÇÃO DO MÓDULO ESCRITA FISCAL - VERSÃO DE OUTUBRO/2024 (10.4A-10)
A3: NE | B3: SAI Origem | C3: Ano SAI Origem | D3: Tipo SAI Origem | E3: Responsável PSAI | F3: Responsável SAI | G3: Análise dos Erros
A4: 88732 | B4: 20373 | C4: 2012 | D4: SAIL
A5: 89152 | B5: 77258 | C5: 2022 | D5: SAL | E5: Cibele | F5: Marielli | G5: Não foi tratado o movimento de contrato imobiliário na SAI origem. Definiu o 1900 considerando todos os movimentos de saídas/serviços, menos contrato.
A6: 89773 | B6: 73747 | C6: 2022 | D6: SAIL | E6: Lais | F6: Marielli | G6: Para o registro C191 deve ser avaliado com a UF se deve ser gerado o registro para entradas e saídas devido a obrigatriedade.
A7: 89963 | B7: 88600 | C7: 2024 | D7: SAL | E7: Luciana | F7: Patrícia | G7: Não foi avaliado o CFOP interrestadual, caso ouvese duas notas com os CFOP 1.xxx e 2.xxx teria realizado a definição correta, e analise do manual do informativo. | H7: Grave
A8: 90082 | B8: 84108 | C8: 2024 | D8: SAL | E8: Priscila | F8: Lais | G8: Foi tratado um registro como reflexo e não era reflexos e quando o desenvolvimento alertou não analisou de forma correta e também não validou com o especialista.
G9: Não tratou Falha na revisão sem confirmar com o especialista na alteração dos campos, não foi tratado os registros os registros M400 e M800.
A17: Total de NEs liberadas | C17: 32
A18: NE's com definição | C18: 5 | D18: =C18/C17 -> 0.15625
A19: NE's com definição recentes | C19: 4 | D19: =C19/C17 -> 0.125

Sheet Novembro 2024 - Importação
A1: LEVANTAMENTO DE NEs COM DEFINIÇÃO DO MÓDULO IMPORTAÇÃO PADRÃO - VERSÃO DE SETEMBRO/2024 (10.4A-09)
A3: NE | B3: SAI Origem | C3: Ano SAI Origem | D3: Tipo SAI Origem | E3: Responsável PSAI | F3: Responsável SAI | G3: Analise dos Erros
A4: 89839 | B4: 80843 | C4: 2023 | D4: NE | E4: Carolina | F4: Carolina | G4: Interna.
A5: 89035 | B5: 86460 | C5: 2024 | D5: SAM | E5: Carolina | F5: Victor | G5: Interna.
A15: Total de NEs liberadas | C15: 15
A16: NE's com definição | C16: 2 | D16: =C16/C15 -> 0.13333333
A17: NE's com definição recentes | C17: 1 | D17: =C17/C15 -> 0.066666667

Sheet Resumo2024
A1: NEs liberadas | B1: NEs com definição | C1: Percentual | E1: NEs por analistas | H1: NEs por especialistas
E2: Juliana | F2: 7
A3: 297 | B3: 30 | C3: =B3/A3 -> 0.1010101 | E3: Felipi Ferreira | F3: 4 | H3: Bruna | I3: 4
E4: Bárbara Mello | F4: 3 | H4: Giovani | I4: 9
E5: Filipe Santos | F5: 2 | H5: Victor | I5: 4
E6: Sabrine | F6: 1 | H6: Lais | I6: 5
E7: Renan | F7: 1
E8: Victor | F8: 1
E9: Carolina | F9: 2
E10: Rafaela | F10: 1

Sheet Janeiro 2025 - Escrita
A1: LEVANTAMENTO DE NEs COM DEFINIÇÃO DO MÓDULO ESCRITA FISCAL - VERSÃO DE JANEIRO/2025 (10.5A-01)
A3: NE | B3: SAI Origem | C3: Ano SAI Origem | D3: Tipo SAI Origem | E3: Responsável PSAI | F3: Responsável SAI | G3: Análise dos Erros
A4: 89629 | B4: 71834 | C4: 2021 | D4: - | E4: - | F4: -
A5: 89464 | B5: 44674 | C5: 2016 | D5: -
A11: Total de NEs liberadas | C11: 19
A12: NE's com definição | C12: 2 | D12: =C12/C11 -> 0.10526316
A13: NE's com definição recentes | C13: 0 | D13: =C13/C11 -> 0

Sheet Janeiro 2025 - Importação
A1: LEVANTAMENTO DE NEs COM DEFINIÇÃO DO MÓDULO IMPORTAÇÃO PADRÃO - VERSÃO DE JANEIRO/2025 (10.5A-01)
A3: NE | B3: Interna | C3: SAI Origem | D3: Ano SAI Origem | E3: Tipo SAI Origem | F3: Responsável PSAI | G3: Responsável SAI | H3: Analise dos Erros
A4: 89523 | B4: Não | C4: 77330 | D4: 2023 | E4: SAM | F4: Renan | G4: Giovani | H4: Foi definido incorretamente a consideração da opção "Deduzir o valor do imposto IPI da base de cálculo" no cálculo do imposto 27.
A5: 89913 | B5: Não | C5: 82801 | D5: 2023 | E5: SAM | F5: Carolina | G5: Victor | H5: Definição ausente. Não foi analisada com a devida atenção da Escrita 71749
A6: 90626 | B6: Não | C6: 22295 | D6: 2012 | E6: SAM | F6: - | G6: -
A15: Total de NEs liberadas | D15: 15
A16: NE's com definição | D16: 3 | E16: =D16/D15 -> 0.2
A17: NE's com definição recentes | D17: 2 | E17: =D17/D15 -> 0.13333333

Sheet Fevereiro 2025 - Escrita
A1: LEVANTAMENTO DE NEs COM DEFINIÇÃO DO MÓDULO ESCRITA FISCAL - VERSÃO DE JANEIRO/2025 (10.5A-01)
A3: NE | B3: SAI Origem | C3: Ano SAI Origem | D3: Tipo SAI Origem | E3: Responsável PSAI | F3: Responsável SAI | G3: Análise dos Erros
A4: 91665 | B4: 91126 | C4: 2024 | D4: SAIL | E4: Felipi de Oliveira Ferreira | F4: Patricia Wesler de Costa | G4: Faltou fazer uma analise com resolução baixa
A5: 90840 | B5: 80117 | C5: 2023 | D5: SAL | E5: Priscila Pereira Silva | F5: Giovani Sangaletti Cunha | G5: Não foi definida a opção do acumulador
A6: 90824 | B6: 64287 | C6: 2020 | D6: SAIL | E6: Patricia Wesler de Costa | F6: Vanessa Custodia Martins | G6: Não foi definida com a opção desmarcada "[ ] Gera lançamentos contábeis por nota", deverá gerar a contabilização por apuração, em "Movimentos/Integração Contábil".
A7: 90858 | B7: 36022 | C7: 2015 | D7: SAIL | E7: Thais Nunes de Souza | F7: Vanessa Custodia Martins | G7: Esquecido de fazer um tratamento de uma mensagem
D8: -
A11: Total de NEs liberadas | C11: 24
A12: NE's com definição | C12: 4 | D12: =C12/C11 -> 0.16666667
A13: NE's com definição recentes | C13: 2 | D13: =C13/C11 -> 0.083333333

Sheet Fevereiro 2025 - Importação
A1: LEVANTAMENTO DE NEs COM DEFINIÇÃO DO MÓDULO IMPORTAÇÃO PADRÃO - VERSÃO DE JANEIRO/2025 (10.5A-01)
A3: NE | B3: Interna | C3: SAI Origem | D3: Ano SAI Origem | E3: Tipo SAI Origem | F3: Responsável PSAI | G3: Responsável SAI | H3: Analise dos Erros
A4: 91580 | B4: Não | C4: -
A5: 90467 | B5: Não | C5: -
A6: 90300 | B6: Não | C6: 85059 | D6: 2024 | E6: SAL | F6: Rafaela | G6: Bruna | H6: Não foi gerado a SAI de reflexo para importação
A7: 90470 | B7: Não | C7: 74333 | D7: 2022 | E7: SAM | F7: Victor | G7: Victor
A8: 90361 | B8: Não | C8: 35685 | D8: 2015 | E8: SAIL | F8: Patrícia | G8: Edegar | H8: Não foi gerado a SAI de reflexo para importação
A15: Total de NEs liberadas | D15: 17
A16: NE's com definição | D16: 5 | E16: =D16/D15 -> 0.29411765
A17: NE's com definição recentes | D17: 1 | E17: =D17/D15 -> 0.058823529

Sheet Março 2025 - Escrita
A1: LEVANTAMENTO DE NEs COM DEFINIÇÃO DO MÓDULO ESCRITA FISCAL - VERSÃO DE JANEIRO/2025 (10.5A-01)
A3: NE | B3: SAI Origem | C3: Ano SAI Origem | D3: Tipo SAI Origem | E3: Responsável PSAI | F3: Responsável SAI | G3: Análise dos Erros
A4: 92775 | B4: 90909 | C4: 2024 | D4: SAIL | E4: Barbara Fernanda Leite | F4: Lais Benetti de Andrade | G4: Ajustado a definição para atender o comportametno do site
A5: 92472 | B5: 91126 | C5: 2024 | D5: SAIL | E5: Felipi de Oliveira Ferreira | F5: Patricia Wesler de Costa
A6: 92395 | B6: 73453 | C6: 2022 | D6: SAIL | E6: Clarice Hendler Magnus | F6: Patricia Wesler de Costa | G6: faltou definir os registros H005, H0101 e H030
A10: Total de NEs liberadas | C10: 27
A11: NE's com definição | C11: 3 | D11: =C11/C10 -> 0.11111111
A12: NE's com definição recentes | C12: 2 | D12: =C12/C10 -> 0.074074074

Sheet Março 2025 - Importação
A1: LEVANTAMENTO DE NEs COM DEFINIÇÃO DO MÓDULO IMPORTAÇÃO PADRÃO - VERSÃO DE JANEIRO/2025 (10.5A-01)
A3: NE | B3: Interna | C3: SAI Origem | D3: Ano SAI Origem | E3: Tipo SAI Origem | F3: Responsável PSAI | G3: Responsável SAI | H3: Analise dos Erros
A4: 91827 | B4: Não | C4: 28398 | D4: 2015 | E4: SAM | F4: Marcio | G4: Daniel | H4: Definição não informada
A5: 90813 | B5: Não | C5: 78890 | D5: 2023 | E5: SAM | F5: Renan das Neves Maiato | G5: Victor Velho Ferreira | H5: Não foi avaliado todos impactos
A6: 92149 | B6: Não | C6: - | D6: - | E6: - | F6: - | G6: - | H6: Sem origem informada
A7: 91503 | B7: Não | C7: - | D7: - | E7: - | F7: - | G7: - | H7: Sem origem informada
A15: Total de NEs liberadas | D15: 14
A16: NE's com definição | D16: 4 | E16: =D16/D15 -> 0.28571429
A17: NE's com definição recentes | D17: 1 | E17: =D17/D15 -> 0.071428571

Sheet Abril 2025 - Escrita
A1: LEVANTAMENTO DE NEs COM DEFINIÇÃO DO MÓDULO ESCRITA FISCAL - VERSÃO DE JANEIRO/2025 (10.5A-01)
A3: NE | B3: SAI Origem | C3: Ano SAI Origem | D3: Tipo SAI Origem | E3: Responsável PSAI | F3: Responsável SAI | G3: Análise dos Erros
A4: 93479 | B4: n/a
A5: 93046 | B5: 91914 | C5: 2025 | D5: SAL | E5: Felipi de Oliveira Ferreira | F5: Lais Benetti de Andrade | G5: NE Interna
A6: 92461 | B6: 39242 | C6: 2015 | D6: SAL | E6: Tamara | F6: Mariana Sartori | G6: faltou definir os registros H005, H0101 e H030
A11: Total de NEs liberadas | C11: 27
A12: NE's com definição | C12: 3 | D12: =C12/C11 -> 0.11111111
A13: NE's com definição recentes | C13: 0 | D13: =C13/C11 -> 0

Sheet Abril 2025 - Importação
A1: LEVANTAMENTO DE NEs COM DEFINIÇÃO DO MÓDULO IMPORTAÇÃO PADRÃO - VERSÃO DE JANEIRO/2025 (10.5A-01)
A3: NE | B3: SAI Origem | C3: Ano SAI Origem | D3: Tipo SAI Origem | E3: Responsável PSAI | F3: Responsável SAI | G3: Analise dos Erros
A4: 91986 | B4: 61979 | C4: 2019 | D4: SAM | E4: Vanessa Martins | F4: Patricia Wesler Costa
A5: 91797 | B5: 18084 | C5: 2011 | D5: SAM | E5: Edegar Souza cruz | F5: Edegar Souza cruz
A15: Total de NEs liberadas | C15: 7
A16: NE's com definição | C16: 2 | D16: =C16/C15 -> 0.28571429
A17: NE's com definição recentes | C17: 0 | D17: =C17/C15 -> 0

Sheet Maio 2025 - Escrita 
A1: LEVANTAMENTO DE NEs COM DEFINIÇÃO DO MÓDULO ESCRITA FISCAL - VERSÃO DE JANEIRO/2025 (10.5A-01)
A3: NE | B3: SAI Origem | C3: Ano SAI Origem | D3: Tipo SAI Origem | E3: Responsável PSAI | F3: Responsável SAI | G3: Análise dos Erros
A4: 93834 | B4: 91200 | C4: 2024 | D4: SAL | E4: Juliana Kuerten | F4: Patricia wesler
A5: 93598 | B5: 35686 | C5: 2015 | D5: SAIL | E5: Patricia wesler | F5: Edegar
A6: 92822 | B6: 50777 | C6: 2017 | D6: SAM | E6: Francine | F6: Vanessa
A7: 92367 | B7: n/a | F7: 3
A11: Total de NEs liberadas | C11: 21
A12: NE's com definição | C12: 4 | D12: =C12/C11 -> 0.19047619
A13: NE's com definição recentes | C13: 1 | D13: =C13/C11 -> 0.047619048

Sheet Maio 2025 - Importação
A1: LEVANTAMENTO DE NEs COM DEFINIÇÃO DO MÓDULO IMPORTAÇÃO PADRÃO - VERSÃO DE JANEIRO/2025 (10.5A-01)
A3: NE | B3: Interna | C3: SAI Origem | D3: Ano SAI Origem | E3: Tipo SAI Origem | F3: Responsável PSAI | G3: Responsável SAI | H3: Analise dos Erros
A4: 94124 | B4: Não | C4: 92022 | D4: 2025 | E4: SAM | F4: Carolina | G4: Victor | H4: Os arquivos que tinhamos na implementação não possuiam esta TAG, apesar de ela constar no manual
A5: 93954 | B5: Sim | C5: 93834 | D5: 2025 | E5: NE | F5: Jennifer | G5: Jennifer | H5: SAI de NE da Escrita que refletiu na importação
A6: 92253 | B6: Não | C6: 52053 | D6: 2018 | E6: SAM | F6: Denner | G6: Marilha
A7: 92109 | B7: Não | H7: Não encontrada
A8: 92210 | B8: Não | C8: 62017 | D8: 2019 | E8: SAM | F8: Victor | G8: Daniel
A15: Total de NEs liberadas | D15: 14
A16: NE's com definição | D16: 5 | E16: =D16/D15 -> 0.35714286
A17: NE's com definição recentes | D17: 2 | E17: =D17/D15 -> 0.14285714

Sheet Junho 2025 - Escrita 
A1: LEVANTAMENTO DE NEs COM DEFINIÇÃO DO MÓDULO ESCRITA FISCAL - VERSÃO DE JUNHO/2025 (10.5A-06)
A3: NE | B3: SAI Origem | C3: Ano SAI Origem | D3: Tipo SAI Origem | E3: Responsável PSAI | F3: Responsável SAI | G3: Análise dos Erros
A4: 94822 | B4: 91469 | C4: 2025 | D4: SAIL | E4: Rafaela | F4: Laís | G4: No registro D700, campo 13 do SPED Fiscal definiu para considerar o valor do campo "Valor Serviço", sendo o correto considerar a "Base de cálculo" da linha do imposto 1-ICMS
A5: 94458 | B5: n/a | G5: Não tem SAI de origem.
A6: 93271 | B6: 20303 | C6: 2012 | D6: SAIL | E6: Mariana | F6: Edegar | G6: Não foi definido a contabilização do ICMS referente ao crédito nas aquisições de Simples Nacional.
A7: 92873 | B7: 28899 | C7: 2014 | D7: SAM | E7: Aline (Contábil.) | F7: Daniel (Contabil.) | G7: Quando criada a janela de conciliação de contas pelo módulo Contabilidade, não foi definido o comportamento no utilitário regerar para que não fossem gerados lançamentos com conta conciliada.
A8: 92838 | B8: 74162 | C8: 2022 | D8: NE | E8: Jennifer | F8: Jennifer | G8: A definição não previu a alteração no acumulador, que também impacta no CFOP no caso de estar marcado "Discriminar CFOP para o lançamento"
A12: Total de NEs liberadas | C12: 23
A13: NE's com definição | C13: 5 | D13: =C13/C12 -> 0.2173913
A14: NE's com definição recentes | C14: 1 | D14: =C14/C12 -> 0.043478261

Sheet Junho 2025 - Importação
A1: LEVANTAMENTO DE NEs COM DEFINIÇÃO DO MÓDULO IMPORTAÇÃO PADRÃO - VERSÃO DE JUNHO/2025 (10.5A-06)
A3: NE | B3: Interna | C3: SAI Origem | D3: Ano SAI Origem | E3: Tipo SAI Origem | F3: Responsável PSAI | G3: Responsável SAI | H3: Analise dos Erros
A4: 94723 | B4: Não | C4: 88823 | D4: 2024 | E4: SAM | F4: Carolina | G4: Victor | H4: Não foi previsto o ajuste feito nas parcelas para o imposto Funrural
A5: 92940 | B5: Não | C5: 80560 | D5: 2023 | E5: SAM | F5: Carolina | G5: Victor | H5: Definição da SAI utiliza uma fórmula diferente para o campo do valor do imposto
A6: 93167 | B6: Não
A12: Total de NEs liberadas | D12: 12
A13: NE's com definição | D13: 3 | E13: =D13/D12 -> 0.25
A14: NE's com definição recentes | D14: 2 | E14: =D14/D12 -> 0.16666667

Sheet Julho 2025 - Escrita
A1: LEVANTAMENTO DE NEs COM DEFINIÇÃO DO MÓDULO ESCRITA FISCAL - VERSÃO DE JULHO/2025 (10.5A-07)
A3: NE | B3: SAI Origem | C3: Ano SAI Origem | D3: Tipo SAI Origem | E3: Responsável PSAI | F3: Responsável SAI | G3: Análise dos Erros
A4: 95200 | B4: 92838 | C4: 2025 | D4: NE | E4: Mateus | F4: Richardson
A5: 94946 | B5: 79994 | C5: 2023 | D5: SAIL | E5: Laís | F5: Giovani | G5: Não foi prevista a situação para geração do EFD Contribuições onde o CTe substituído não possuir valor de PIS/COFINS
A6: 94868 | B6: 79994 | C6: 2023 | D6: SAIL | E6: Laís | F6: Giovani | G6: Não foi definido a contabilização do estorno do valor da nota do CT-e substituído (foi previsto apenas o estorno dos impostos)
A7: 94819 | B7: 49498 | C7: 2017 | D7: SAIL | E7: Sibeli | F7: Mariana | G7: Definição incompleta na contabilização do estorno de crédito de ICMS nas operações com CP.
A8: 94555 | B8: 79994 | C8: 2023 | D8: SAIL | E8: Laís | F8: Giovani | G8: Não foi considerado na definição a opção "Deduzir
G10: 4
A12: Total de NEs liberadas | C12: 20
A13: NE's com definição | C13: 5 | D13: =C13/C12 -> 0.25
A14: NE's com definição recentes | C14: 4 | D14: =C14/C12 -> 0.2

Sheet Julho 2025 - Importação
A1: LEVANTAMENTO DE NEs COM DEFINIÇÃO DO MÓDULO IMPORTAÇÃO PADRÃO - VERSÃO DE JULHO/2025 (10.5A-07)
A3: NE | B3: SAI Origem | C3: Ano SAI Origem | D3: Tipo SAI Origem | E3: Responsável PSAI | F3: Responsável SAI | G3: Analise dos Erros
A12: Total de NEs liberadas | C12: 9
A13: NE's com definição | C13: 0 | D13: =C13/C12 -> 0
A14: NE's com definição recentes | D14: =C14/C12 -> 0

Sheet Agosto 2025 - Escrita
A1: LEVANTAMENTO DE NEs COM DEFINIÇÃO DO MÓDULO ESCRITA FISCAL - VERSÃO DE AGOSTO/2025 (10.5A-08)
A3: NE | B3: SAI Origem | C3: Ano SAI Origem | D3: Tipo SAI Origem | E3: Responsável PSAI | F3: Responsável SAI | G3: Análise dos Erros
A4: SAI-95847 | B4: SAI-89930 | C4: 2025 | D4: SAM | E4: Renan | F4: Giovani | G4: Problema de experiência do usuário, onde os usuários não compreenderam que o novo fluxo exigia confirmar a tela filha e gravar a tela mãe, onde a reclamação foi que o sistema não vinculava as contas.
A5: SAI-95720 | B5: SAI-93539 | C5: 2025 | D5: SAIL | E5: Giana | F5: Laís | G5: NE interna
A6: SAI-95737 | B6: SAI-94870 | C6: 2025 | D6: SAL | E6: Fabio | F6: Patricia | G6: Na definição da SAI não foi previsto definição para a opção "Apuração consolidada conforme Art. 55 §5º
A7: SAI-95619 | B7: SAI-78961 | C7: 2024 | D7: SAIL | E7: Juliana | F7: Giovani | G7: Faltou definição para a tag FolhaSalario no mês de abertura da empresa.
A8: SAI-93923 | B8: SAI-60788 | C8: 2019 | D8: SAIL | E8: Sibeli | F8: Vanessa | G8: Não foi considerado que na guia "Entradas" poderia haver mais de 1 linha de ICMS, ocasionando valor incorreto no SPED.
G10: 4
A12: Total de NEs liberadas | C12: 31
A13: NE's com definição | C13: 5 | D13: =C13/C12 -> 0.16129032
A14: NE's com definição recentes | C14: 4 | D14: =C14/C12 -> 0.12903226

Sheet Agosto 2025 - Importação
A1: LEVANTAMENTO DE NEs COM DEFINIÇÃO DO MÓDULO IMPORTAÇÃO PADRÃO - VERSÃO DE AGOSTO/2025 (10.5A-08)
A3: NE | B3: SAI Origem | C3: Ano SAI Origem | D3: Tipo SAI Origem | E3: Responsável PSAI | F3: Responsável SAI | G3: Analise dos Erros
A4: SAI-95047 | B4: SAI-82065 | C4: 2024 | D4: SAM | E4: Sabrine | F4: Victor | G4: Retirado a mensagem de validação "CNPJ da chave é diferente do CNPJ da SCP"
A5: SAI-94633 | B5: SAI-32508 | C5: 2016 | D5: SAM | E5: Marcio | F5: Daniel | G5: Complemento de definição quando marcado a opção "Gera documento de Utilização de beneficio - DUB-ICMS"
A6: 94193 | B6: 35911 | C6: 2015 | D6: SAM | E6: Marcio | F6: Marcio | G6: Situação não definida
A7: 94192 | B7: 78956 | C7: 2023 | D7: SAM | E7: Sabrine | F7: Victor | G7: Situação não definida
A12: Total de NEs liberadas | C12: 19
A13: NE's com definição | C13: 4 | D13: =C13/C12 -> 0.21052632
A14: NE's com definição recentes | C14: 2 | D14: =C14/C12 -> 0.10526316

Sheet Setembro 2025 - Escrita
A1: LEVANTAMENTO DE NEs COM DEFINIÇÃO DO MÓDULO ESCRITA FISCAL - VERSÃO DE SETEMBRO/2025 (10.5A-09)
A3: NE | B3: SAI Origem | C3: Ano SAI Origem | D3: Tipo SAI Origem | E3: Responsável PSAI | F3: Responsável SAI | G3: Análise dos Erros
A4: 96576 | B4: 95528 | C4: 2025 | D4: SAL | E4: Rafaela Sampaio | F4: Patrícia | G4: Para o código RS000013 não é obrigatório o preenchindo da guia "Detalhamento"
A5: 96378 | B5: 94081 | C5: 2025 | D5: SAL | E5: Fábio | F5: Patrícia | G5: Não foi definida a geração do registro E115 para o código de ajuste RJ028001
A6: 96089 | B6: 91200 | C6: 2025 | D6: SAL | E6: Juliana | F6: Patrícia | G6: Não foi citado na definição que a condição deveria se aplicar também para filiais
A7: 95769 | B7: 69736 | C7: 2021 | D7: SAM | E7: Juliana | F7: Patrícia | G7: Não foi previsto o caso do crédito presumido ser menor que a devolução e estorno pela entrada
A8: 95102 | B8: 83156 | C8: 2024 | D8: SAM | E8: Rafaela Ribeiro | F8: Giovani | G8: Para o imposto 63 não foi definida a ordem correta da onde pegar a natureza do rendimento quando o fato gerador for 'pagamento'
A9: 94947 | B9: 67944 | C9: 2020 | D9: SAM | E9: Daniela Eyng | F9: Mariana | G9: Na SAI 67944 não foi previsto o caso específico para MG que gera os valores de isentas e outras na guia "Estadual\Geral"
A12: Total de NEs liberadas | C12: 36
A13: NE's com definição | C13: 6 | D13: =C13/C12 -> 0.16666667
A14: NE's com definição recentes | C14: 4 | D14: =C14/C12 -> 0.11111111

Sheet Setembro 2025 - Importação
A1: LEVANTAMENTO DE NEs COM DEFINIÇÃO DO MÓDULO IMPORTAÇÃO PADRÃO - VERSÃO DE SETEMBRO/2025 (10.5A-09)
A3: NE | B3: SAI Origem | C3: Ano SAI Origem | D3: Tipo SAI Origem | E3: Responsável PSAI | F3: Responsável SAI | G3: Analise dos Erros
A4: 95006 | B4: 53824 | C4: 2018 | D4: SAM | E4: Sibeli | F4: Mariana | G4: Situação não definida
A5: 94807 | B5: 44394 | C5: 2016 | D5: NE | E5: Ghisi | F5: Richardson | G5: Situação não definida
A12: Total de NEs liberadas | C12: 10
A13: NE's com definição | C13: 2 | D13: =C13/C12 -> 0.2
A14: NE's com definição recentes | D14: =C14/C12 -> 0

Sheet Outubro 2025 - Escrita
A1: LEVANTAMENTO DE NEs COM DEFINIÇÃO DO MÓDULO ESCRITA FISCAL - VERSÃO DE OUTUBRO/2025 (10.5A-10)
A3: NE | B3: SAI Origem | C3: Ano SAI Origem | D3: Tipo SAI Origem | E3: Responsável PSAI | F3: Responsável SAI | G3: Análise dos Erros
A4: 97080 | B4: 93484 | C4: 2025 | D4: SAL | E4: Karoline | F4: Giovani | G4: Definição da SAI origem deixou de gerar um código que ainda estava vigente e tinha que gerar em algumas situações
A5: 96953 | B5: 92829 | C5: 2025 | D5: SAL | E5: Mateus | F5: Lais | G5: A SAI origem não deixou claro a condição que deveria funcionar também quando existisse base de cálculo informada para o ICMS
A6: 96455 | B6: 36057 | C6: 2015 | D6: SAL | E6: Marielli | F6: Antonio | G6: Na SAI origem define para a opção habilitar quando tiver notas com espécie NFCe-, mas nesse caso somente a filial tinha, sendo assim na matriz não habilita, porém o informativo é gerado na matriz.
A7: 96456 | B7: 71523 | C7: 2021 | D7: SAL | E7: Igor | F7: Marielli | G7: Nenhuma SAI define a condição de códigos de recolhimento diferentes para o 22 e 23, com fato gerador 'data de saída'.
A8: 96068 | B8: 44248 | C8: 2016 | D8: SAIL | E8: Vanessa | F8: Edegar | G8: SAI origem não define o comportamento do agrupamento no relatório quando possuir o mesmo produto informado mais de uma vez.
A9: 95771 | B9: 82446 | C9: 2024 | D9: SAL | E9: Priscila | F9: Giovani | G9: O cálculo é feito com 4 casas mas o relatório da memória demonstra 2, dessa forma os valores não ficavam corretos.
A12: Total de NEs liberadas | C12: 30
A13: NE's com definição | C13: 6 | D13: =C13/C12 -> 0.2
A14: NE's com definição recentes | C14: 3 | D14: =C14/C12 -> 0.1

Sheet Outubro 2025 - Importação
A1: LEVANTAMENTO DE NEs COM DEFINIÇÃO DO MÓDULO IMPORTAÇÃO PADRÃO - VERSÃO DE SETEMBRO/2025 (10.5A-09)
A3: NE | B3: SAI Origem | C3: Ano SAI Origem | D3: Tipo SAI Origem | E3: Responsável PSAI | F3: Responsável SAI | G3: Analise dos Erros
A4: 97275 | B4: 95299 | C4: 2025 | D4: SAM | E4: Caroline | F4: Victor | G4: Situação não definida
A5: 97135 | B5: 94312 | C5: 2025 | D5: SAM | E5: Victor | F5: Victor | G5: A definção que "provocou" o erro, foi decidia em conjunto com o desenvolvimento, pois são casos muito específicos e técnicos do cliente Focus
A6: 96411 | B6: 18098 | C6: 2011 | D6: SAM | E6: Sem responsável | F6: Antonio | G6: SAI muito antiga, quando não tinha definições
A7: 96118 | B7: 91929 | C7: 2025 | D7: SAM | E7: Erick | F7: Victor | G7: Situação não definida
A12: Total de NEs liberadas | C12: 14
A13: NE's com definição | C13: 4 | D13: =C13/C12 -> 0.28571429
A14: NE's com definição recentes | C14: 3 | D14: =C14/C12 -> 0.21428571

Sheet Novembro 2025 - Escrita
A1: LEVANTAMENTO DE NEs COM DEFINIÇÃO DO MÓDULO ESCRITA FISCAL - VERSÃO DE NOVEMBRO/2025 (10.5A-11)
A3: NE | B3: SAI Origem | C3: Ano SAI Origem | D3: Tipo SAI Origem | E3: Responsável PSAI | F3: Responsável SAI | G3: Análise dos Erros
A4: 98137 | B4: 96572 | C4: 2025 | D4: SAIL | E4: Juliana | F4: Bruna | G4: Não foi previsto casos onde houvesse ICMS desonerado, porém sem SUBTRI informado (CST de SUBTRI)
A5: 97761 | B5: 96434 | C5: 2025 | D5: SAL | E5: Flavia | F5: Bruna | G5: Não foi colocado na SAI origem o demonstrativo, porém ajustando a apuração o demonstrativo não é alterado, o desenvolvedor precisa entrar no relatório opara fazer alteração
A6: 97766 | B6: 94148 | C6: 2025 | D6: SAIL | E6: Bárbara Melo | F6: Lais | G6: A definição é para no relatório considerar todos os impostos da apuração, mas o correto seria não considerar os impostos 183 e 184
A7: 97507 | B7: 28860 | C7: 2014 | D7: SAIL | E7: Joziani | F7: Edegar | G7: Não foram tratados alguns CFOPs no quadro V | H7: alguns
A8: 96856 | B8: 80472 | C8: 2023 | D8: SAIL | E8: Juliana | F8: Lais | G8: Situação não tratada na SAI origem
A9: 96463 | B9: 50304 | C9: 2018 | D9: SAL | E9: Bruna | F9: Vanessa | G9: A fórmula do cálculo do DIFALI por nota estava incorreta
A10: 95302 | B10: 57552 | C10: 2019 | D10: SAM | E10: Rogério | F10: Vanessa | G10: Não foi tratada a integração com o tipo "Sintético"
A12: Total de NEs liberadas | C12: 40
A13: NE's com definição | C13: 7 | D13: =C13/C12 -> 0.175
A14: NE's com definição recentes | C14: 3 | D14: =C14/C12 -> 0.075

Sheet Novembro 2025 - Importação
A1: LEVANTAMENTO DE NEs COM DEFINIÇÃO DO MÓDULO IMPORTAÇÃO PADRÃO - VERSÃO DE SETEMBRO/2025 (10.5A-09)
A3: NE | B3: SAI Origem | C3: Ano SAI Origem | D3: Tipo SAI Origem | E3: Responsável PSAI | F3: Responsável SAI | G3: Analise dos Erros
A4: 97853 | B4: 95510/96708/96174 | C4: 2025 | D4: SAM | E4: Daniela | F4: Victor | G4: NE Interna, itens da reforma tributária
A5: 96610 | B5: 50305 | C5: 2017 | D5: SAM | E5: Bruna | F5: Vanessa | G5: Situação não definida
A6: 96522 | B6: 52585 | C6: 2018 | D6: SAM | E6: Denner | F6: Marieli | G6: Situação não definida
A12: Total de NEs liberadas | C12: 12
A13: NE's com definição | C13: 3 | D13: =C13/C12 -> 0.25
A14: NE's com definição recentes | C14: 1 | D14: =C14/C12 -> 0.083333333

Sheet Dezembro 2025 - Escrita
A1: LEVANTAMENTO DE NEs COM DEFINIÇÃO DO MÓDULO ESCRITA FISCAL - VERSÃO DE DEZEMBRO/2025 (10.5A-12)
A3: NE | B3: SAI Origem | C3: Ano SAI Origem | D3: Tipo SAI Origem | E3: Responsável PSAI | F3: Responsável SAI | G3: Análise dos Erros
A4: 96734 | B4: 49587 | C4: 2017 | D4: SAL | E4: - | F4: - | G4: -
A5: 96855 | B5: 85209 | C5: 2024 | D5: SAIL | E5: Juliana | F5: Lais | G5: A SAI origem não menciona que os registros 45 e 47 não devem ser gerados para os CFOPs 1.663, 1.664, 2.663, 2.664, 5.663, 5.664, 5.665, 5.666, 6.663, 6.664, 6.665, 6.666.
A6: 97217 | B6: 22408 | C6: 2012 | D6: SAL | E6: - | F6: - | G6: -
A7: 97209 | B7: não possui | C7: - | D7: - | E7: - | F7: - | G7: - | H7: alguns
A8: 97915 | B8: 11130 | D8: - | E8: - | F8: - | G8: NE Interna.
A9: 98046 | B9: 93614 | C9: 2025 | D9: SAM | E9: Fábio | F9: Giovani | G9: SAI de origem não definiu que deveria tratar caracteres especiais no nome da empresa.
A10: 98070 | B10: 96822 | C10: 2025 | D10: SAIL | E10: Bárbara Melo | F10: Lais | G10: Não foi definido para buscar pelo NCM completo e após o NCM parcial.
A11: 98236 | B11: 88347 | C11: 2024 | D11: SAM | E11: Renan | F11: Lais | G11: Definição para o cálculo da CBS e IBS para não considerar os impostos 22-PIS Retido e 23-COFINS Retida.
A14: Total de NEs liberadas | C14: 30
A15: NE's com definição | C15: 8 | D15: =C15/C14 -> 0.26666667
A16: NE's com definição recentes | C16: 4 | D16: =C16/C14 -> 0.13333333

Sheet Dezembro 2025 - Importação
A1: LEVANTAMENTO DE NEs COM DEFINIÇÃO DO MÓDULO IMPORTAÇÃO PADRÃO - VERSÃO DE SETEMBRO/2025 (10.5A-09)
A3: NE | B3: SAI Origem | C3: Ano SAI Origem | D3: Tipo SAI Origem | E3: Responsável PSAI | F3: Responsável SAI | G3: Analise dos Erros
A4: 98678 | B4: 98473 | C4: 2025 | D4: SAM | E4: Carolina | F4: Victor | G4: Reflexo não definido
A5: 97293 | B5: 94676/94678 | C5: 2025 | D5: SAM | E5: Daniela | F5: Victor | G5: NE Interna, itens da reforma tributária
A6: 97269 | B6: 95510 | C6: 2025 | D6: SAM | E6: Daniela | F6: Victor | G6: NE Interna, itens da reforma tributária
A12: Total de NEs liberadas | C12: 9
A13: NE's com definição | C13: 3 | D13: =C13/C12 -> 0.33333333
A14: NE's com definição recentes | C14: 3 | D14: =C14/C12 -> 0.33333333

Sheet Resumo2025
A1: Escrita
A2: Versão | B2: NEs liberadas | C2: NEs com definição | D2: Percentual 2024/2025 | E2: Definição Antiga | F2: Percentual Geral | G2: NEs Com Definição 2024/2025 | I2: NEs por analistas | L2: NEs por especialistas
A3: Janeiro | B3: 19 | C3: 2 | D3: =(C3-E3)/B3 -> 0 | E3: 2 | F3: =C3/B3 -> 0.10526316 | G3: =C3-E3 -> 0 | I3: Juliana | J3: 5 | L3: Jennifer | M3: 1
A4: Fevereiro | B4: 24 | C4: 4 | D4: =(C4-E4)/B4 -> 0.041666667 | E4: 3 | F4: =C4/B4 -> 0.16666667 | G4: =C4-E4 -> 1 | I4: Felipi Ferreira | J4: 3 | L4: Bruna | M4: 0
A5: Março | B5: 27 | C5: 3 | D5: =(C5-E5)/B5 -> 0.037037037 | E5: 2 | F5: =C5/B5 -> 0.11111111 | G5: =C5-E5 -> 1 | I5: Bárbara Leite | J5: 1 | L5: Giovani | M5: 11
A6: Abril | B6: 27 | C6: 3 | D6: =(C6-E6)/B6 -> 0.037037037 | E6: 2 | F6: =C6/B6 -> 0.11111111 | G6: =C6-E6 -> 1 | I6: Bárbara Mello | J6: 1 | L6: Victor | M6: 8
A7: Maio | B7: 21 | C7: 4 | D7: =(C7-E7)/B7 -> 0.047619048 | E7: 3 | F7: =C7/B7 -> 0.19047619 | G7: =C7-E7 -> 1 | I7: Erick | J7: 1 | L7: Lais | M7: 7
A8: Junho | B8: 23 | C8: 5 | D8: =(C8-E8)/B8 -> 0.043478261 | E8: 4 | F8: =C8/B8 -> 0.2173913 | G8: =C8-E8 -> 1 | I8: Sabrine | J8: 1 | L8: Patricia | M8: 8
A9: Julho | B9: 20 | C9: 5 | D9: =(C9-E9)/B9 -> 0.05 | E9: 4 | F9: =C9/B9 -> 0.25 | G9: =C9-E9 -> 1 | I9: Renan | J9: 4
A10: Agosto | B10: 31 | C10: 5 | D10: =(C10-E10)/B10 -> 0.12903226 | E10: 1 | F10: =C10/B10 -> 0.16129032 | G10: =C10-E10 -> 4 | I10: Fábio | J10: 3 | L10: Total | M10: =SUM(M3:M8) -> 35
A11: Setembro | B11: 36 | C11: 6 | D11: =(C11-E11)/B11 -> 0.11111111 | E11: 2 | F11: =C11/B11 -> 0.16666667 | G11: =C11-E11 -> 4 | I11: Carolina | J11: 6
A12: Outubro | B12: 30 | C12: 6 | D12: =(C12-E12)/B12 -> 0.1 | E12: 3 | F12: =C12/B12 -> 0.2 | G12: =C12-E12 -> 3 | I12: Rafaela Ribeiro | J12: 2
A13: Novembro | B13: ='Novembro 2025 - Escrita'!C12 -> 40 | C13: ='Novembro 2025 - Escrita'!C13 -> 7 | D13: =(C13-E13)/B13 -> 0.075 | E13: 4 | F13: =C13/B13 -> 0.175 | G13: =C13-E13 -> 3 | I13: Rafaela Sampaio | J13: 1
A14: Dezembro | B14: ='Dezembro 2025 - Escrita'!C14 -> 30 | C14: ='Dezembro 2025 - Escrita'!C15 -> 8 | D14: =(C14-E14)/B14 -> 0.13333333 | E14: 4 | F14: =C14/B14 -> 0.26666667 | G14: =C14-E14 -> 4 | I14: Matheus | J14: 2
A15: TOTAL: | B15: =SUM(B3:B14) -> 328 | C15: =SUM(C3:C14) -> 58 | D15: =(C15-E15)/B15 -> 0.073170732 | E15: =SUM(E3:E14) -> 34 | F15: =C15/B15 -> 0.17682927 | G15: =SUM(G3:G14) -> 24 | I15: Total | J15: =SUM(J3:J14) -> 30
A17: Importação
A18: Versão | B18: NEs liberadas | C18: NEs com definição | D18: Percentual | E18: Definição Antiga | F18: Percentual Geral
A19: Janeiro | B19: 15 | C19: 3 | D19: =(C19-E19)/B19 -> 0 | E19: 3 | F19: =C19/B19 -> 0.2 | G19: =C19-E19 -> 0
A20: Fevereiro | B20: 17 | C20: 5 | D20: =(C20-E20)/B20 -> 0.058823529 | E20: 4 | F20: =C20/B20 -> 0.29411765 | G20: =C20-E20 -> 1
A21: Março | B21: 14 | C21: 4 | D21: =(C21-E21)/B21 -> 0 | E21: 4 | F21: =C21/B21 -> 0.28571429 | G21: =C21-E21 -> 0
A22: Abril | B22: 7 | C22: 2 | D22: =(C22-E22)/B22 -> 0 | E22: 2 | F22: =C22/B22 -> 0.28571429 | G22: =C22-E22 -> 0
A23: Maio | B23: 14 | C23: 5 | D23: =(C23-E23)/B23 -> 0.14285714 | E23: 3 | F23: =C23/B23 -> 0.35714286 | G23: =C23-E23 -> 2
A24: Junho | B24: 12 | C24: 3 | D24: =(C24-E24)/B24 -> 0.16666667 | E24: 1 | F24: =C24/B24 -> 0.25 | G24: =C24-E24 -> 2
A25: Julho | B25: 9 | C25: 0 | D25: =(C25-E25)/B25 -> 0 | E25: 0 | F25: =C25/B25 -> 0 | G25: =C25-E25 -> 0
A26: Agosto | B26: 19 | C26: 4 | D26: =(C26-E26)/B26 -> 0.052631579 | E26: 3 | F26: =C26/B26 -> 0.21052632 | G26: =C26-E26 -> 1
A27: Setembro | B27: 10 | C27: 2 | D27: =(C27-E27)/B27 -> 0 | E27: 2 | F27: =C27/B27 -> 0.2 | G27: =C27-E27 -> 0
A28: Outubro | B28: 14 | C28: 4 | D28: =(C28-E28)/B28 -> 0.21428571 | E28: 1 | F28: =C28/B28 -> 0.28571429 | G28: =C28-E28 -> 3
A29: Novembro | B29: 12 | C29: 3 | D29: =(C29-E29)/B29 -> 0.083333333 | E29: 2 | F29: =C29/B29 -> 0.25 | G29: =C29-E29 -> 1
A30: Dezembro | B30: 9 | C30: 3 | D30: =(C30-E30)/B30 -> 0.33333333 | E30: 0 | F30: =C30/B30 -> 0.33333333 | G30: =C30-E30 -> 3
A31: TOTAL: | B31: =SUM(B19:B30) -> 152 | C31: =SUM(C19:C30) -> 38 | D31: =(C31-E31)/B31 -> 0.085526316 | E31: =SUM(E19:E30) -> 25 | F31: =C31/B31 -> 0.25 | G31: =SUM(G19:G30) -> 13
F34: Total Geral | G34: =G15+G31 -> 37
A35: 2025
A36: Total de NEs liberadas | C36: =B31+B15 -> 480
A37: NE's com definição | C37: =C15+C31 -> 96 | D37: =C37/C36 -> 0.2
A38: NE's com definição recentes | C38: =G15+G31 -> 37 | D38: =C38/C36 -> 0.077083333
A39: NE's sem origem ou origem igual/anterior a 2022 | C39: =C37-C38 -> 59 | D39: =C39/C36 -> 0.12291667
A40: 2026
A41: Total de NEs liberadas | C41: 124
A42: NE's com definição | C42: 27 | D42: =C42/C41 -> 0.21774194
A43: NE's com definição recentes | C43: 13 | D43: 0.1
...

Sheet Janeiro 2026 - Escrita
A1: LEVANTAMENTO DE NEs COM DEFINIÇÃO DO MÓDULO ESCRITA FISCAL - VERSÃO DE JANEIRO/2026 (10.6A-01)
A3: NE | B3: SAI Origem | C3: Ano SAI Origem | D3: Tipo SAI Origem | E3: Responsável PSAI | F3: Responsável SAI | G3: Análise dos Erros | H3: Considera
A4: 98974 | B4: 97321 | C4: 2025 | D4: SAL | E4: Flávia | F4: Giovani | G4: Não vejo que seja um erro da GP, apesar de ter definição. Entendo que o desenvolvimento deveria ter passado a limitação. | H4: Sim
A5: 98843 | B5: 96700 | C5: 2025 | D5: SAL | E5: Rafaela Ribeiro | F5: Giovani | G5: Faltou definição de quando não existir o imposto 55 no lançamento e a base de cálculo do ICMS for diferente de zero | H5: Sim
A6: 98542 | B6: 96822 | C6: 2025 | D6: SAIL | E6: Bárbara Melo | F6: Lais | G6: Faltou definir o utilitário de alterar notas e outros lançamentos. | H6: Sim
A7: 98545 | B7: 15405 | C7: 2011 | D7: SAIL | F7: Edegar | G7: Não existia definição de como devria ser o comportamento dos registros M100 e M500 em casos que no período possua apenas devolução de compras, sem crédito | H7: Não
A8: 98333 | B8: 81160 | C8: 2023 | D8: SAIL | F8: Laís | G8: Não existe na tabela do Reinf o país 'Inglaterra', então tem que gerar o código do reino unido. | H8: Não
A9: 97911 | B9: 79501 | C9: 2023 | D9: SAL | E9: Priscila | F9: Bruna | G9: Não existia definição de quando o percentual do ICMS fosse gerado. | H9: Não
A10: 97253 | B10: 62262 | C10: 2019 | D10: SAL | E10: Denner | F10: Bruna | G10: Não foi tratado o utilitário. | H10: Não
A11: 97238 | B11: 43181 | C11: 2016 | D11: SAL | E11: Débora | F11: Mariana | G11: Não foi definido zeramento. | H11: Não
A14: Total de NEs liberadas | C14: 29
A15: NE's com definição | C15: 8 | D15: =C15/C14 -> 0.27586207
A16: NE's com definição recentes | C16: 3 | D16: =C16/C14 -> 0.10344828

Sheet Janeiro 2026 - Importação 
A1: LEVANTAMENTO DE NEs COM DEFINIÇÃO DO MÓDULO IMPORTAÇÃO PADRÃO - VERSÃO DE SETEMBRO/2025 (10.5A-09)
A3: NE | B3: SAI Origem | C3: Ano SAI Origem | D3: Tipo SAI Origem | E3: Responsável PSAI | F3: Responsável SAI | G3: Analise dos Erros | H3: Considera
A4: 98953 | B4: 97104 | C4: 2025 | D4: SAM | E4: Carolina Esmeraldino | F4: Victor Ferreira | G4: Não foi revisado a SAI para retirar a opção de importar o cancelamento | H4: Sim
A5: 98807 | B5: 91445 | C5: 2025 | D5: SAM | E5: Carolina Esmeraldino | F5: Victor Ferreira | G5: Não foi definido a situação de outros valores para itens que não possuem CST de ICMS | H5: Sim
A6: 97920 | B6: 79502 | C6: 2023 | D6: SAM | E6: Priscila Silva | F6: Bruna Ferro | G6: Não foi definido o ponto de verificação no percentual de redução do ICMS | H6: Não
A12: Total de NEs liberadas | C12: 8
A13: NE's com definição | C13: 3 | D13: =C13/C12 -> 0.375
A14: NE's com definição recentes | C14: 2 | D14: =C14/C12 -> 0.25

Sheet Fevereiro 2026 - Escrita
A1: LEVANTAMENTO DE NEs COM DEFINIÇÃO DO MÓDULO ESCRITA FISCAL - VERSÃO DE FEVEREIRO/2026 (10.6A-02)
A3: NE | B3: SAI Origem | C3: Ano SAI Origem | D3: Tipo SAI Origem | E3: Responsável PSAI | F3: Responsável SAI | G3: Análise dos Erros | H3: Considera
A4: 99218 | B4: 98138 | C4: 2025 | D4: SAL | E4: Renan | F4: Lais | G4: Percentual não definido na SAI de origem | H4: Sim
A5: 99301 | B5: 96730 | C5: 2025 | D5: NE | E5: Jennifer | F5: Jennifer | G5: SAI revisada e tirada a definição. | H5: Não
A6: 99919 | B6: não possui | H6: Não
A7: 99959 | B7: não possui | H7: Não
A15: Total de NEs liberadas | C15: 31
A16: NE's com definição | C16: 3 | D16: =C16/C15 -> 0.096774194
A17: NE's com definição recentes | C17: 1 | D17: =C17/C15 -> 0.032258065

Sheet Fevereiro 2026 - Importação 
A1: LEVANTAMENTO DE NEs COM DEFINIÇÃO DO MÓDULO IMPORTAÇÃO PADRÃO - VERSÃO DE FEVEREIRO/2026 (10.6A-02)
A3: NE | B3: SAI Origem | C3: Ano SAI Origem | D3: Tipo SAI Origem | E3: Responsável PSAI | F3: Responsável SAI | G3: Analise dos Erros | H3: Considera
A4: 98504 | B4: 85624 | C4: 2024 | D4: SAM Imp | E4: Sabrine | F4: Victor | G4: A SAI origem não possuía definição para contexto de matriz/filial com compartilhamento de contas. | H4: Sim
A5: 97964 | B5: --- | C5: -- | D5: SAM Escrita | E5: -- | F5: -- | G5: SAI Origem provavelmente foi a SAI que criou o importador ou que criou o imposto 49 | H5: Não
A12: Total de NEs liberadas | C12: 12
A13: NE's com definição | C13: 2 | D13: =C13/C12 -> 0.16666667
A14: NE's com definição recentes | C14: 1 | D14: =C14/C12 -> 0.083333333

Sheet Março 2026 - Escrita
A1: LEVANTAMENTO DE NEs COM DEFINIÇÃO DO MÓDULO ESCRITA FISCAL - VERSÃO DE MARÇO/2026 (10.6A-02)
A3: NE | B3: SAI Origem | C3: Ano SAI Origem | D3: Tipo SAI Origem | E3: Responsável PSAI | F3: Responsável SAI | G3: Análise dos Erros | H3: Considera
A4: 100342 | B4: 97877 | C4: 2025 | D4: SAL | E4: Felipi | F4: Patrícia | G4: Criou regra com vinculo do imposto no acumulador ao invés de olhar diretamente a nota. Importa o imposto e não tem no acumulador. | H4: Sim | I4: Alterações do SPED que vinculou os impostos CBS/IBS ao acumulador ao invés de olhar a nota.
A5: 100306 | B5: não possui | H5: Não
A6: 100319 | B6: 99223 | C6: 2026 | D6: SAL | E6: Juliana | F6: Lais | G6: Majoração mais que 100% documento não fiscal. | H6: Sim | I6: Causa já reportada no RDM da majoração
A7: 100250 | B7: 99351 | C7: 2026 | D7: SAIL | E7: Bárbara Melo | F7: Bruna | G7: Vinculo incorreto com o Fornecedor. | H7: Sim | I7: Causa já reportada NE crítica
A8: 100230 | B8: 91471 | C8: 2025 | D8: SAIL | E8: Felipi | F8: Patrícia | G8: Foi definido comportamento para Sócio Ostensiva e SCPs Lucro Real. Não foi tratado uma delas sendo LP e que teria nota lançada na Escrita | H8: Sim | I8: Uma variável não analisada e prevista
A9: 100187 | B9: 99797 | C9: 2026 | D9: NE | E9: Jennifer | F9: Jennifer | G9: Não corrigiu o comprovante que não gerou o sócio. | H9: Sim | I9: Causa já reportada NE grave
A10: 100046 | B10: não possui | G10: NE interna | H10: Não
A11: 100053 | B11: 99772 | C11: 2026 | D11: SAL | E11: Fábio | F11: Bruna | G11: Definido percentual de 11,09% e não 11,9%. | H11: Sim | I11: Falha na definição.
A14: Total de NEs liberadas | C14: 33
A15: NE's com definição | C15: 8 | D15: =C15/C14 -> 0.24242424
A16: NE's com definição recentes | C16: 6 | D16: =C16/C14 -> 0.18181818 | E16: =C16/44 -> 0.13636364

Sheet Março 2026 - Importação
A1: LEVANTAMENTO DE NEs COM DEFINIÇÃO DO MÓDULO IMPORTAÇÃO PADRÃO - VERSÃO DE MARÇO/2026 (10.6A-03)
A3: NE | B3: SAI Origem | C3: Ano SAI Origem | D3: Tipo SAI Origem | E3: Responsável PSAI | F3: Responsável SAI | G3: Analise dos Erros | H3: Considera
A4: 98813 | B4: 79089 | C4: 2023 | D4: SAM | E4: Sabrine | F4: Victor | H4: Não
A5: 99811 | B5: não possui | H5: Não
A12: Total de NEs liberadas | C12: 11 | E12: =C12+'Março 2026 - Escrita'!C14 -> 44
A13: NE's com definição | C13: 2 | D13: =C13/C12 -> 0.18181818
A14: NE's com definição recentes | C14: 0 | D14: =C14/C12 -> 0
A18: 2026
A19: Total de NEs liberadas | D19: 124
A20: NE's com definição | D20: 27 | E20: 0.22
A21: NE's com definição recentes | D21: 13 | E21: 0.1

Sheet Abril 2026 - Escrita
A1: LEVANTAMENTO DE NEs COM DEFINIÇÃO DO MÓDULO ESCRITA FISCAL - VERSÃO DE ABRIL/2026 (10.6A-02)
A3: NE | B3: SAI Origem | C3: Ano SAI Origem | D3: Tipo SAI Origem | E3: Responsável PSAI | F3: Responsável SAI | G3: Análise dos Erros | H3: Considera
A4: 101120 | B4: 99223 | C4: 2026 | D4: SAL | E4: Juliana | F4: Lais | G4: SAI origem considerava 6 casas decimais no cálculo, foi necessário aumentar para 20 | H4: Sim | I4: Grave
A5: 100945 | B5: 98596 | C5: 2025 | D5: SAIL | E5: Juliana | F5: Bruna | G5: Não foi definido o reflexo totalizador da DIME quando possui saldo credor. | H5: Sim
A6: 100803 | B6: 99962 | C6: 2026 | D6: SAIL | E6: Bárbara Leite | F6: Bruna | G6: NE interna | H6: Não
A7: 100805 | B7: 28051 | C7: 2013 | H7: Não
A8: 100524 | B8: 74975 | C8: 2022 | D8: SAM | E8: Cibele | F8: Giovani | G8: NE interna | H8: Não
A9: 100498 | B9: 94293 | C9: 2025 | D9: SAL | E9: Mateus | F9: Giovani | G9: NE interna | H9: Não
A10: 100347 | B10: 80871 | C10: 2023 | D10: SAL | H10: Não
A11: 99834 | B11: 80472 | C11: 2023 | D11: SAIL | E11: Juliana | F11: Lais | H11: Não
A12: 99605 | B12: 88979 | C12: 2024 | D12: SAL | E12: Priscila | F12: Giovani | G12: Não foi definido nos relatórios para desconsiderar a opção do acumulador nas notas de devolução de compra. | H12: Sim
A13: 99332 | B13: não possui | H13: Não
A14: 98961 | B14: 78986 | C14: 2023 | D14: SAL | E14: Felipi | F14: Bruna | H14: Não
A15: 98546 | B15: não possui | H15: Não
A18: Total de NEs liberadas | C18: 45
A19: NE's com definição | C19: 12 | D19: =C19/C18 -> 0.26666667
A20: NE's com definição recentes | C20: 3 | D20: =C20/C18 -> 0.066666667

Sheet Abril 2026 - Importação
A1: LEVANTAMENTO DE NEs COM DEFINIÇÃO DO MÓDULO IMPORTAÇÃO PADRÃO - VERSÃO DE ABRIL/2026 (10.6A-03)
A3: NE | B3: SAI Origem | C3: Ano SAI Origem | D3: Tipo SAI Origem | E3: Responsável PSAI | F3: Responsável SAI | G3: Analise dos Erros | H3: Considera
A12: Total de NEs liberadas | C12: 6
A13: NE's com definição | C13: 0 | D13: =C13/C12 -> 0
A14: NE's com definição recentes | C14: 0 | D14: =C14/C12 -> 0

Sheet Maio 2026 - Escrita
A1: LEVANTAMENTO DE NEs COM DEFINIÇÃO DO MÓDULO ESCRITA FISCAL - VERSÃO DE MAIO/2026 (10.6A-05)
A3: NE | B3: SAI Origem | C3: Ano SAI Origem | D3: Tipo SAI Origem | E3: Responsável PSAI | F3: Responsável SAI | G3: Análise dos Erros | H3: Considera
A4: 95994 | B4: 513 | C4: 2003 | D4: SAM | E4: - | F4: - | H4: Não | I4: Grave
A5: 100410 | B5: não possui | C5: - | D5: - | E5: - | F5: - | H5: Não
A6: 100539 | B6: 95295 | C6: 2025 | D6: SAIL | E6: Bárbara Melo | F6: Lais | G6: Não considerou que os relatórios podem ser emitidos mais de um imposto junto e criou mensagem que bloqueou esse comportamento. | H6: Sim
A7: 100807 | B7: 9608 | C7: 2008 | D7: SAL | E7: - | F7: - | H7: Não
A8: 101212 | B8: 35004 | C8: 2015 | D8: SAM | E8: - | F8: - | H8: Não
A9: =101262 -> 101262 | B9: 94014 | C9: 2025 | D9: SAIL | E9: Mateus | F9: Lais | G9: Não foi tratado mensagem na API considerando a possibilidade de bloqueio temporário no DW | H9: Sim
A10: 101508 | B10: 100580 | C10: 2026 | D10: SAM | E10: Bárbara Leite | F10: Bruna | G10: Não foi detalhado os movimentos que deveriam refletir no relatório. | H10: Sim
A11: 101657 | B11: não possui | C11: - | D11: - | E11: - | F11: - | H11: Não
A12: 101698 | B12: 99351 | C12: 2026 | D12: SAIL | E12: Bárbara Melo | F12: Bruna | G12: Não avaliou o comportamento da versão de mercado para definir um campo que já tínhamos em outro ponto no sistema. | H12: Sim
A18: Total de NEs liberadas | C18: 40
A19: NE's com definição | C19: 9 | D19: =C19/C18 -> 0.225
A20: NE's com definição recentes | C20: 4 | D20: =C20/C18 -> 0.1

Sheet Maio 2026 - Importação
A1: LEVANTAMENTO DE NEs COM DEFINIÇÃO DO MÓDULO IMPORTAÇÃO PADRÃO - VERSÃO DE MAIO/2026 (10.6A-05)
A3: NE | B3: SAI Origem | C3: Ano SAI Origem | D3: Tipo SAI Origem | E3: Responsável PSAI | F3: Responsável SAI | G3: Analise dos Erros | H3: Considera
A4: 99996 | B4: 36998 | C4: 2015 | D4: SAM | E4: Marcio | F4: Marcio | G4: Não foi definido a alíquota de ISS para a guia "Itens" | H4: Não
A5: 100941 | B5: 97466 | C5: 2025 | D5: SAM | E5: Carolina | F5: Victor | G5: Definimos os campos necessários e os demais devia manter mercado, porém o manter mercado do campo "Cod. Rec" quando o imposto estiver "Lançado por produto" caia numa rotina específica e ficou incorreto. Entendemos que nesse caso houve também erro do teste | H5: Não
A6: 101319 | B6: 79446 | C6: 2023 | D6: SAM | E6: Victor | F6: Victor | G6: Não foi incluído validação de verificação do nome do País ao identificar o município | H6: Sim
A7: 101432 | B7: 97104 | C7: 2025 | D7: SAM | E7: Carolina | F7: Victor | G7: Comportamento indetectável devido a NFS-e possuir um fluxo um pouco diferente da NF-e ao baixar do Web Service da Receita | H7: Sim
A12: Total de NEs liberadas | C12: 17
A13: NE's com definição | C13: 4 | D13: =C13/C12 -> 0.23529412
A14: NE's com definição recentes | C14: 2 | D14: =C14/C12 -> 0.11764706

Sheet Junho 2026 - Escrita
A1: LEVANTAMENTO DE NEs COM DEFINIÇÃO DO MÓDULO ESCRITA FISCAL - VERSÃO DE MAIO/2026 (10.6A-05)
A3: NE | B3: SAI Origem | C3: Ano SAI Origem | D3: Tipo SAI Origem | E3: Responsável PSAI | F3: Responsável SAI | G3: Análise dos Erros | H3: Considera
A4: 101492 | B4: 13569 | C4: 2010 | H4: Não
